Workbook

Sheet Assumptions
A1: écentic shpk — Financial Model
A2: All inputs in this tab feed downstream tabs. Edit yellow cells to recalculate.
A3: Currency: EUR (€) · Period: 36 months starting July 2026 · FX assumption: 1 USD = 0.92 EUR
A5: STARTING POSITION (June 2026)
A6: Cash on hand (€) | B6: 4000
A7: Current MRR (€) | B7: 200
A8: Current burn (€/mo) | B8: 400
A9: Paying customers (count) | B9: 1
A11: ROUND ASSUMPTIONS
A12: Round size (€) | B12: 300000
A13: Round close month (1 = July 2026) | B13: 1
A14: Post-money valuation (€) | B14: 4000000
A15: Investor ownership | B15: =B12/B14
A17: PRICING (EUR, blended from USD list price × 0.92)
A18: Tier 1 — Connect (€/mo) | B18: =149*0.92
A19: Tier 2 — Compete (€/mo) | B19: =499*0.92
A20: Tier 3 — Dominate (€/mo) | B20: =999*0.92
A21: Agency audit avg (€, one-time) | B21: 5000
A22: Enterprise pilot ACV (€/yr) | B22: 37500
A24: CUSTOMER MIX (% of SaaS subscribers per tier)
A25: Tier 1 share | B25: 0.7
A26: Tier 2 share | B26: 0.2
A27: Tier 3 share | B27: 0.1
A28: Blended ARPA (€/mo) | B28: =B18*B25+B19*B26+B20*B27
A30: GROWTH ASSUMPTIONS
A31: New self-serve customers M1 (post-raise) | B31: 3
A32: Monthly growth rate (compounding) | B32: 0.18
A33: Monthly logo churn | B33: 0.04
A34: Enterprise pilots closed Year 1 | B34: 2
A35: Audit projects per month (steady state, from M6) | B35: 2
A37: COSTS (monthly run-rate by category)
A38: Founder salary (each, €/mo, starts M3) | B38: 1500
A39: Engineer salary gross (€/mo) | B39: 2500
A40: GTM/Sales hire (€/mo) | B40: 2800
A41: Cloud + infra (€/mo, scaled) | B41: 400
A42: AI/LLM API spend (€/mo, M1) | B42: 150
A43: AI/LLM spend growth per customer (€/mo each) | B43: 8
A44: Tools & SaaS (€/mo) | B44: 300
A45: Legal/accounting (€/mo) | B45: 250
A46: Marketing & content (€/mo) | B46: 500
...

Sheet P&L 36 Months
A1: P&L Projection — 36 Months
A2: July 2026 → June 2029 · Driven by Assumptions tab
A4: Line Item | B4: M1 | C4: M2 | D4: M3 | E4: M4 | F4: M5 | G4: M6 | H4: M7 | I4: M8 | J4: M9 | K4: M10 | L4: M11 | M4: M12 | N4: M13 | O4: M14 | P4: M15 | Q4: M16 | R4: M17 | S4: M18 | T4: M19 | U4: M20 | V4: M21 | W4: M22 | X4: M23 | Y4: M24 | Z4: M25 | AA4: M26 | AB4: M27 | AC4: M28 | AD4: M29 | AE4: M30 | AF4: M31 | AG4: M32 | AH4: M33 | AI4: M34 | AJ4: M35 | AK4: M36 | AL4: Year 1 Total | AM4: Year 2 Total | AN4: Year 3 Total
A5: New self-serve customers / month | B5: =Assumptions!B31 | C5: =ROUND(B5*(1+Assumptions!B$32),0) | D5: =ROUND(C5*(1+Assumptions!B$32),0) | E5: =ROUND(D5*(1+Assumptions!B$32),0) | F5: =ROUND(E5*(1+Assumptions!B$32),0) | G5: =ROUND(F5*(1+Assumptions!B$32),0) | H5: =ROUND(G5*(1+Assumptions!B$32),0) | I5: =ROUND(H5*(1+Assumptions!B$32),0) | J5: =ROUND(I5*(1+Assumptions!B$32),0) | K5: =ROUND(J5*(1+Assumptions!B$32),0) | L5: =ROUND(K5*(1+Assumptions!B$32),0) | M5: =ROUND(L5*(1+Assumptions!B$32),0) | N5: =ROUND(M5*(1+Assumptions!B$32),0) | O5: =ROUND(N5*(1+Assumptions!B$32),0) | P5: =ROUND(O5*(1+Assumptions!B$32),0) | Q5: =ROUND(P5*(1+Assumptions!B$32),0) | R5: =ROUND(Q5*(1+Assumptions!B$32),0) | S5: =ROUND(R5*(1+Assumptions!B$32),0) | T5: =ROUND(S5*(1+Assumptions!B$32),0) | U5: =ROUND(T5*(1+Assumptions!B$32),0) | V5: =ROUND(U5*(1+Assumptions!B$32),0) | W5: =ROUND(V5*(1+Assumptions!B$32),0) | X5: =ROUND(W5*(1+Assumptions!B$32),0) | Y5: =ROUND(X5*(1+Assumptions!B$32),0) | Z5: =ROUND(Y5*(1+Assumptions!B$32),0) | AA5: =ROUND(Z5*(1+Assumptions!B$32),0) | AB5: =ROUND(AA5*(1+Assumptions!B$32),0) | AC5: =ROUND(AB5*(1+Assumptions!B$32),0) | AD5: =ROUND(AC5*(1+Assumptions!B$32),0) | AE5: =ROUND(AD5*(1+Assumptions!B$32),0) | AF5: =ROUND(AE5*(1+Assumptions!B$32),0) | AG5: =ROUND(AF5*(1+Assumptions!B$32),0) | AH5: =ROUND(AG5*(1+Assumptions!B$32),0) | AI5: =ROUND(AH5*(1+Assumptions!B$32),0) | AJ5: =ROUND(AI5*(1+Assumptions!B$32),0) | AK5: =ROUND(AJ5*(1+Assumptions!B$32),0) | AL5: =SUM(B5:M5) | AM5: =SUM(N5:Y5) | AN5: =SUM(Z5:AK5)
A6: Active self-serve customers (cumulative, net of churn) | B6: =Assumptions!B9+B5 | C6: =ROUND(B6*(1-Assumptions!B$33)+C5,0) | D6: =ROUND(C6*(1-Assumptions!B$33)+D5,0) | E6: =ROUND(D6*(1-Assumptions!B$33)+E5,0) | F6: =ROUND(E6*(1-Assumptions!B$33)+F5,0) | G6: =ROUND(F6*(1-Assumptions!B$33)+G5,0) | H6: =ROUND(G6*(1-Assumptions!B$33)+H5,0) | I6: =ROUND(H6*(1-Assumptions!B$33)+I5,0) | J6: =ROUND(I6*(1-Assumptions!B$33)+J5,0) | K6: =ROUND(J6*(1-Assumptions!B$33)+K5,0) | L6: =ROUND(K6*(1-Assumptions!B$33)+L5,0) | M6: =ROUND(L6*(1-Assumptions!B$33)+M5,0) | N6: =ROUND(M6*(1-Assumptions!B$33)+N5,0) | O6: =ROUND(N6*(1-Assumptions!B$33)+O5,0) | P6: =ROUND(O6*(1-Assumptions!B$33)+P5,0) | Q6: =ROUND(P6*(1-Assumptions!B$33)+Q5,0) | R6: =ROUND(Q6*(1-Assumptions!B$33)+R5,0) | S6: =ROUND(R6*(1-Assumptions!B$33)+S5,0) | T6: =ROUND(S6*(1-Assumptions!B$33)+T5,0) | U6: =ROUND(T6*(1-Assumptions!B$33)+U5,0) | V6: =ROUND(U6*(1-Assumptions!B$33)+V5,0) | W6: =ROUND(V6*(1-Assumptions!B$33)+W5,0) | X6: =ROUND(W6*(1-Assumptions!B$33)+X5,0) | Y6: =ROUND(X6*(1-Assumptions!B$33)+Y5,0) | Z6: =ROUND(Y6*(1-Assumptions!B$33)+Z5,0) | AA6: =ROUND(Z6*(1-Assumptions!B$33)+AA5,0) | AB6: =ROUND(AA6*(1-Assumptions!B$33)+AB5,0) | AC6: =ROUND(AB6*(1-Assumptions!B$33)+AC5,0) | AD6: =ROUND(AC6*(1-Assumptions!B$33)+AD5,0) | AE6: =ROUND(AD6*(1-Assumptions!B$33)+AE5,0) | AF6: =ROUND(AE6*(1-Assumptions!B$33)+AF5,0) | AG6: =ROUND(AF6*(1-Assumptions!B$33)+AG5,0) | AH6: =ROUND(AG6*(1-Assumptions!B$33)+AH5,0) | AI6: =ROUND(AH6*(1-Assumptions!B$33)+AI5,0) | AJ6: =ROUND(AI6*(1-Assumptions!B$33)+AJ5,0) | AK6: =ROUND(AJ6*(1-Assumptions!B$33)+AK5,0) | AL6: =M6 | AM6: =Y6 | AN6: =AK6
A7: Enterprise pilots active | B7: 0 | C7: 0 | D7: 0 | E7: 0 | F7: 0 | G7: 1 | H7: 1 | I7: 1 | J7: 1 | K7: 2 | L7: 2 | M7: 2 | N7: 2 | O7: 2 | P7: 2 | Q7: 4 | R7: 4 | S7: 4 | T7: 4 | U7: 4 | V7: 4 | W7: 4 | X7: 4 | Y7: 6 | Z7: 6 | AA7: 6 | AB7: 6 | AC7: 6 | AD7: 6 | AE7: 6 | AF7: 6 | AG7: 6 | AH7: 6 | AI7: 6 | AJ7: 6 | AK7: 6 | AL7: =M7 | AM7: =Y7 | AN7: =AK7
A8: MRR — self-serve (€) | B8: =B6*Assumptions!B$28 | C8: =C6*Assumptions!B$28 | D8: =D6*Assumptions!B$28 | E8: =E6*Assumptions!B$28 | F8: =F6*Assumptions!B$28 | G8: =G6*Assumptions!B$28 | H8: =H6*Assumptions!B$28 | I8: =I6*Assumptions!B$28 | J8: =J6*Assumptions!B$28 | K8: =K6*Assumptions!B$28 | L8: =L6*Assumptions!B$28 | M8: =M6*Assumptions!B$28 | N8: =N6*Assumptions!B$28 | O8: =O6*Assumptions!B$28 | P8: =P6*Assumptions!B$28 | Q8: =Q6*Assumptions!B$28 | R8: =R6*Assumptions!B$28 | S8: =S6*Assumptions!B$28 | T8: =T6*Assumptions!B$28 | U8: =U6*Assumptions!B$28 | V8: =V6*Assumptions!B$28 | W8: =W6*Assumptions!B$28 | X8: =X6*Assumptions!B$28 | Y8: =Y6*Assumptions!B$28 | Z8: =Z6*Assumptions!B$28 | AA8: =AA6*Assumptions!B$28 | AB8: =AB6*Assumptions!B$28 | AC8: =AC6*Assumptions!B$28 | AD8: =AD6*Assumptions!B$28 | AE8: =AE6*Assumptions!B$28 | AF8: =AF6*Assumptions!B$28 | AG8: =AG6*Assumptions!B$28 | AH8: =AH6*Assumptions!B$28 | AI8: =AI6*Assumptions!B$28 | AJ8: =AJ6*Assumptions!B$28 | AK8: =AK6*Assumptions!B$28 | AL8: =SUM(B8:M8) | AM8: =SUM(N8:Y8) | AN8: =SUM(Z8:AK8)
A9: MRR — enterprise (€) | B9: =B7*Assumptions!B$22/12 | C9: =C7*Assumptions!B$22/12 | D9: =D7*Assumptions!B$22/12 | E9: =E7*Assumptions!B$22/12 | F9: =F7*Assumptions!B$22/12 | G9: =G7*Assumptions!B$22/12 | H9: =H7*Assumptions!B$22/12 | I9: =I7*Assumptions!B$22/12 | J9: =J7*Assumptions!B$22/12 | K9: =K7*Assumptions!B$22/12 | L9: =L7*Assumptions!B$22/12 | M9: =M7*Assumptions!B$22/12 | N9: =N7*Assumptions!B$22/12 | O9: =O7*Assumptions!B$22/12 | P9: =P7*Assumptions!B$22/12 | Q9: =Q7*Assumptions!B$22/12 | R9: =R7*Assumptions!B$22/12 | S9: =S7*Assumptions!B$22/12 | T9: =T7*Assumptions!B$22/12 | U9: =U7*Assumptions!B$22/12 | V9: =V7*Assumptions!B$22/12 | W9: =W7*Assumptions!B$22/12 | X9: =X7*Assumptions!B$22/12 | Y9: =Y7*Assumptions!B$22/12 | Z9: =Z7*Assumptions!B$22/12 | AA9: =AA7*Assumptions!B$22/12 | AB9: =AB7*Assumptions!B$22/12 | AC9: =AC7*Assumptions!B$22/12 | AD9: =AD7*Assumptions!B$22/12 | AE9: =AE7*Assumptions!B$22/12 | AF9: =AF7*Assumptions!B$22/12 | AG9: =AG7*Assumptions!B$22/12 | AH9: =AH7*Assumptions!B$22/12 | AI9: =AI7*Assumptions!B$22/12 | AJ9: =AJ7*Assumptions!B$22/12 | AK9: =AK7*Assumptions!B$22/12 | AL9: =SUM(B9:M9) | AM9: =SUM(N9:Y9) | AN9: =SUM(Z9:AK9)
A10: Total MRR (€) | B10: =B8+B9 | C10: =C8+C9 | D10: =D8+D9 | E10: =E8+E9 | F10: =F8+F9 | G10: =G8+G9 | H10: =H8+H9 | I10: =I8+I9 | ... AK10: =AK8+AK9 | AL10: =M10 | AM10: =Y10 | AN10: =AK10
A11: Total ARR (€) | B11: =B10*12 | C11: =C10*12 | D11: =D10*12 | E11: =E10*12 | F11: =F10*12 | G11: =G10*12 | H11: =H10*12 | I11: =I10*12 | ... AK11: =AK10*12 | AL11: =M11 | AM11: =Y11 | AN11: =AK11
A12: Agency audit revenue (€) | B12: 0 | C12: 0 | D12: 0 | E12: 0 | F12: 0 | G12: =Assumptions!B34*Assumptions!B21 | H12: =Assumptions!B34*Assumptions!B21 | I12: =Assumptions!B34*Assumptions!B21 | J12: =Assumptions!B34*Assumptions!B21 | K12: =Assumptions!B34*Assumptions!B21 | L12: =Assumptions!B34*Assumptions!B21 | M12: =Assumptions!B34*Assumptions!B21 | N12: =Assumptions!B34*Assumptions!B21 | O12: =Assumptions!B34*Assumptions!B21 | P12: =Assumptions!B34*Assumptions!B21 | Q12: =Assumptions!B34*Assumptions!B21 | R12: =Assumptions!B34*Assumptions!B21 | S12: =Assumptions!B34*Assumptions!B21 | T12: =Assumptions!B34*Assumptions!B21 | U12: =Assumptions!B34*Assumptions!B21 | V12: =Assumptions!B34*Assumptions!B21 | W12: =Assumptions!B34*Assumptions!B21 | X12: =Assumptions!B34*Assumptions!B21 | Y12: =Assumptions!B34*Assumptions!B21 | Z12: =Assumptions!B34*Assumptions!B21 | AA12: =Assumptions!B34*Assumptions!B21 | AB12: =Assumptions!B34*Assumptions!B21 | AC12: =Assumptions!B34*Assumptions!B21 | AD12: =Assumptions!B34*Assumptions!B21 | AE12: =Assumptions!B34*Assumptions!B21 | AF12: =Assumptions!B34*Assumptions!B21 | AG12: =Assumptions!B34*Assumptions!B21 | AH12: =Assumptions!B34*Assumptions!B21 | AI12: =Assumptions!B34*Assumptions!B21 | AJ12: =Assumptions!B34*Assumptions!B21 | AK12: =Assumptions!B34*Assumptions!B21 | AL12: =SUM(B12:M12) | AM12: =SUM(N12:Y12) | AN12: =SUM(Z12:AK12)
A13: Total monthly revenue (€) | B13: =B10+B12 | C13: =C10+C12 | D13: =D10+D12 | E13: =E10+E12 | F13: =F10+F12 | G13: =G10+G12 | H13: =H10+H12 | I13: =I10+I12 | ... AK13: =AK10+AK12 | AL13: =SUM(B13:M13) | AM13: =SUM(N13:Y13) | AN13: =SUM(Z13:AK13)
A15: COSTS
A16: Founder salaries (3 × €/mo, from M3) | B16: 0 | C16: 0 | D16: =3*Assumptions!B$38 | E16: =3*Assumptions!B$38 | F16: =3*Assumptions!B$38 | G16: =3*Assumptions!B$38 | H16: =3*Assumptions!B$38 | I16: =3*Assumptions!B$38 | J16: =3*Assumptions!B$38 | K16: =3*Assumptions!B$38 | L16: =3*Assumptions!B$38 | M16: =3*Assumptions!B$38 | N16: =3*Assumptions!B$38 | O16: =3*Assumptions!B$38 | P16: =3*Assumptions!B$38 | Q16: =3*Assumptions!B$38 | R16: =3*Assumptions!B$38 | S16: =3*Assumptions!B$38 | T16: =3*Assumptions!B$38 | U16: =3*Assumptions!B$38 | V16: =3*Assumptions!B$38 | W16: =3*Assumptions!B$38 | X16: =3*Assumptions!B$38 | Y16: =3*Assumptions!B$38 | Z16: =3*Assumptions!B$38 | AA16: =3*Assumptions!B$38 | AB16: =3*Assumptions!B$38 | AC16: =3*Assumptions!B$38 | AD16: =3*Assumptions!B$38 | AE16: =3*Assumptions!B$38 | AF16: =3*Assumptions!B$38 | AG16: =3*Assumptions!B$38 | AH16: =3*Assumptions!B$38 | AI16: =3*Assumptions!B$38 | AJ16: =3*Assumptions!B$38 | AK16: =3*Assumptions!B$38 | AL16: =SUM(B16:M16) | AM16: =SUM(N16:Y16) | AN16: =SUM(Z16:AK16)
A17: Engineer #1 (back-end, from M2) | B17: =IF(1>=Assumptions!B$50,Assumptions!B$39,0) | C17: =IF(2>=Assumptions!B$50,Assumptions!B$39,0) | D17: =IF(3>=Assumptions!B$50,Assumptions!B$39,0) | E17: =IF(4>=Assumptions!B$50,Assumptions!B$39,0) | F17: =IF(5>=Assumptions!B$50,Assumptions!B$39,0) | G17: =IF(6>=Assumptions!B$50,Assumptions!B$39,0) | H17: =IF(7>=Assumptions!B$50,Assumptions!B$39,0) | I17: =IF(8>=Assumptions!B$50,Assumptions!B$39,0) | J17: =IF(9>=Assumptions!B$50,Assumptions!B$39,0) | K17: =IF(10>=Assumptions!B$50,Assumptions!B$39,0) | L17: =IF(11>=Assumptions!B$50,Assumptions!B$39,0) | M17: =IF(12>=Assumptions!B$50,Assumptions!B$39,0) | N17: =IF(13>=Assumptions!B$50,Assumptions!B$39,0) | O17: =IF(14>=Assumptions!B$50,Assumptions!B$39,0) | P17: =IF(15>=Assumptions!B$50,Assumptions!B$39,0) | Q17: =IF(16>=Assumptions!B$50,Assumptions!B$39,0) | R17: =IF(17>=Assumptions!B$50,Assumptions!B$39,0) | S17: =IF(18>=Assumptions!B$50,Assumptions!B$39,0) | T17: =IF(19>=Assumptions!B$50,Assumptions!B$39,0) | U17: =IF(20>=Assumptions!B$50,Assumptions!B$39,0) | V17: =IF(21>=Assumptions!B$50,Assumptions!B$39,0) | W17: =IF(22>=Assumptions!B$50,Assumptions!B$39,0) | X17: =IF(23>=Assumptions!B$50,Assumptions!B$39,0) | Y17: =IF(24>=Assumptions!B$50,Assumptions!B$39,0) | Z17: =IF(25>=Assumptions!B$50,Assumptions!B$39,0) | AA17: =IF(26>=Assumptions!B$50,Assumptions!B$39,0) | AB17: =IF(27>=Assumptions!B$50,Assumptions!B$39,0) | AC17: =IF(28>=Assumptions!B$50,Assumptions!B$39,0) | AD17: =IF(29>=Assumptions!B$50,Assumptions!B$39,0) | AE17: =IF(30>=Assumptions!B$50,Assumptions!B$39,0) | AF17: =IF(31>=Assumptions!B$50,Assumptions!B$39,0) | AG17: =IF(32>=Assumptions!B$50,Assumptions!B$39,0) | AH17: =IF(33>=Assumptions!B$50,Assumptions!B$39,0) | AI17: =IF(34>=Assumptions!B$50,Assumptions!B$39,0) | AJ17: =IF(35>=Assumptions!B$50,Assumptions!B$39,0) | AK17: =IF(36>=Assumptions!B$50,Assumptions!B$39,0) | AL17: =SUM(B17:M17) | AM17: =SUM(N17:Y17) | AN17: =SUM(Z17:AK17)
A18: GTM/Sales Lead (from M3) | B18: =IF(1>=Assumptions!B$51,Assumptions!B$40,0) | C18: =IF(2>=Assumptions!B$51,Assumptions!B$40,0) | D18: =IF(3>=Assumptions!B$51,Assumptions!B$40,0) | E18: =IF(4>=Assumptions!B$51,Assumptions!B$40,0) | F18: =IF(5>=Assumptions!B$51,Assumptions!B$40,0) | G18: =IF(6>=Assumptions!B$51,Assumptions!B$40,0) | H18: =IF(7>=Assumptions!B$51,Assumptions!B$40,0) | I18: =IF(8>=Assumptions!B$51,Assumptions!B$40,0) | J18: =IF(9>=Assumptions!B$51,Assumptions!B$40,0) | K18: =IF(10>=Assumptions!B$51,Assumptions!B$40,0) | L18: =IF(11>=Assumptions!B$51,Assumptions!B$40,0) | M18: =IF(12>=Assumptions!B$51,Assumptions!B$40,0) | N18: =IF(13>=Assumptions!B$51,Assumptions!B$40,0) | O18: =IF(14>=Assumptions!B$51,Assumptions!B$40,0) | P18: =IF(15>=Assumptions!B$51,Assumptions!B$40,0) | Q18: =IF(16>=Assumptions!B$51,Assumptions!B$40,0) | R18: =IF(17>=Assumptions!B$51,Assumptions!B$40,0) | S18: =IF(18>=Assumptions!B$51,Assumptions!B$40,0) | T18: =IF(19>=Assumptions!B$51,Assumptions!B$40,0) | U18: =IF(20>=Assumptions!B$51,Assumptions!B$40,0) | V18: =IF(21>=Assumptions!B$51,Assumptions!B$40,0) | W18: =IF(22>=Assumptions!B$51,Assumptions!B$40,0) | X18: =IF(23>=Assumptions!B$51,Assumptions!B$40,0) | Y18: =IF(24>=Assumptions!B$51,Assumptions!B$40,0) | Z18: =IF(25>=Assumptions!B$51,Assumptions!B$40,0) | AA18: =IF(26>=Assumptions!B$51,Assumptions!B$40,0) | AB18: =IF(27>=Assumptions!B$51,Assumptions!B$40,0) | AC18: =IF(28>=Assumptions!B$51,Assumptions!B$40,0) | AD18: =IF(29>=Assumptions!B$51,Assumptions!B$40,0) | AE18: =IF(30>=Assumptions!B$51,Assumptions!B$40,0) | AF18: =IF(31>=Assumptions!B$51,Assumptions!B$40,0) | AG18: =IF(32>=Assumptions!B$51,Assumptions!B$40,0) | AH18: =IF(33>=Assumptions!B$51,Assumptions!B$40,0) | AI18: =IF(34>=Assumptions!B$51,Assumptions!B$40,0) | AJ18: =IF(35>=Assumptions!B$51,Assumptions!B$40,0) | AK18: =IF(36>=Assumptions!B$51,Assumptions!B$40,0) | AL18: =SUM(B18:M18) | AM18: =SUM(N18:Y18) | AN18: =SUM(Z18:AK18)
A19: Engineer #2 (from M6) | B19: =IF(1>=Assumptions!B$52,Assumptions!B$39,0) | C19: =IF(2>=Assumptions!B$52,Assumptions!B$39,0) | D19: =IF(3>=Assumptions!B$52,Assumptions!B$39,0) | E19: =IF(4>=Assumptions!B$52,Assumptions!B$39,0) | F19: =IF(5>=Assumptions!B$52,Assumptions!B$39,0) | G19: =IF(6>=Assumptions!B$52,Assumptions!B$39,0) | H19: =IF(7>=Assumptions!B$52,Assumptions!B$39,0) | I19: =IF(8>=Assumptions!B$52,Assumptions!B$39,0) | J19: =IF(9>=Assumptions!B$52,Assumptions!B$39,0) | K19: =IF(10>=Assumptions!B$52,Assumptions!B$39,0) | L19: =IF(11>=Assumptions!B$52,Assumptions!B$39,0) | M19: =IF(12>=Assumptions!B$52,Assumptions!B$39,0) | N19: =IF(13>=Assumptions!B$52,Assumptions!B$39,0) | O19: =IF(14>=Assumptions!B$52,Assumptions!B$39,0) | P19: =IF(15>=Assumptions!B$52,Assumptions!B$39,0) | Q19: =IF(16>=Assumptions!B$52,Assumptions!B$39,0) | R19: =IF(17>=Assumptions!B$52,Assumptions!B$39,0) | S19: =IF(18>=Assumptions!B$52,Assumptions!B$39,0) | T19: =IF(19>=Assumptions!B$52,Assumptions!B$39,0) | U19: =IF(20>=Assumptions!B$52,Assumptions!B$39,0) | V19: =IF(21>=Assumptions!B$52,Assumptions!B$39,0) | W19: =IF(22>=Assumptions!B$52,Assumptions!B$39,0) | X19: =IF(23>=Assumptions!B$52,Assumptions!B$39,0) | Y19: =IF(24>=Assumptions!B$52,Assumptions!B$39,0) | Z19: =IF(25>=Assumptions!B$52,Assumptions!B$39,0) | AA19: =IF(26>=Assumptions!B$52,Assumptions!B$39,0) | AB19: =IF(27>=Assumptions!B$52,Assumptions!B$39,0) | AC19: =IF(28>=Assumptions!B$52,Assumptions!B$39,0) | AD19: =IF(29>=Assumptions!B$52,Assumptions!B$39,0) | AE19: =IF(30>=Assumptions!B$52,Assumptions!B$39,0) | AF19: =IF(31>=Assumptions!B$52,Assumptions!B$39,0) | AG19: =IF(32>=Assumptions!B$52,Assumptions!B$39,0) | AH19: =IF(33>=Assumptions!B$52,Assumptions!B$39,0) | AI19: =IF(34>=Assumptions!B$52,Assumptions!B$39,0) | AJ19: =IF(35>=Assumptions!B$52,Assumptions!B$39,0) | AK19: =IF(36>=Assumptions!B$52,Assumptions!B$39,0) | AL19: =SUM(B19:M19) | AM19: =SUM(N19:Y19) | AN19: =SUM(Z19:AK19)
A20: Marketing Lead (from M9) | B20: =IF(1>=Assumptions!B$53,Assumptions!B$40,0) | C20: =IF(2>=Assumptions!B$53,Assumptions!B$40,0) | D20: =IF(3>=Assumptions!B$53,Assumptions!B$40,0) | E20: =IF(4>=Assumptions!B$53,Assumptions!B$40,0) | F20: =IF(5>=Assumptions!B$53,Assumptions!B$40,0) | G20: =IF(6>=Assumptions!B$53,Assumptions!B$40,0) | H20: =IF(7>=Assumptions!B$53,Assumptions!B$40,0) | I20: =IF(8>=Assumptions!B$53,Assumptions!B$40,0) | J20: =IF(9>=Assumptions!B$53,Assumptions!B$40,0) | K20: =IF(10>=Assumptions!B$53,Assumptions!B$40,0) | L20: =IF(11>=Assumptions!B$53,Assumptions!B$40,0) | M20: =IF(12>=Assumptions!B$53,Assumptions!B$40,0) | N20: =IF(13>=Assumptions!B$53,Assumptions!B$40,0) | O20: =IF(14>=Assumptions!B$53,Assumptions!B$40,0) | P20: =IF(15>=Assumptions!B$53,Assumptions!B$40,0) | Q20: =IF(16>=Assumptions!B$53,Assumptions!B$40,0) | R20: =IF(17>=Assumptions!B$53,Assumptions!B$40,0) | S20: =IF(18>=Assumptions!B$53,Assumptions!B$40,0) | T20: =IF(19>=Assumptions!B$53,Assumptions!B$40,0) | U20: =IF(20>=Assumptions!B$53,Assumptions!B$40,0) | V20: =IF(21>=Assumptions!B$53,Assumptions!B$40,0) | W20: =IF(22>=Assumptions!B$53,Assumptions!B$40,0) | X20: =IF(23>=Assumptions!B$53,Assumptions!B$40,0) | Y20: =IF(24>=Assumptions!B$53,Assumptions!B$40,0) | Z20: =IF(25>=Assumptions!B$53,Assumptions!B$40,0) | AA20: =IF(26>=Assumptions!B$53,Assumptions!B$40,0) | AB20: =IF(27>=Assumptions!B$53,Assumptions!B$40,0) | AC20: =IF(28>=Assumptions!B$53,Assumptions!B$40,0) | AD20: =IF(29>=Assumptions!B$53,Assumptions!B$40,0) | AE20: =IF(30>=Assumptions!B$53,Assumptions!B$40,0) | AF20: =IF(31>=Assumptions!B$53,Assumptions!B$40,0) | AG20: =IF(32>=Assumptions!B$53,Assumptions!B$40,0) | AH20: =IF(33>=Assumptions!B$53,Assumptions!B$40,0) | AI20: =IF(34>=Assumptions!B$53,Assumptions!B$40,0) | AJ20: =IF(35>=Assumptions!B$53,Assumptions!B$40,0) | AK20: =IF(36>=Assumptions!B$53,Assumptions!B$40,0) | AL20: =SUM(B20:M20) | AM20: =SUM(N20:Y20) | AN20: =SUM(Z20:AK20)
A21: Customer Success (from M12) | B21: =IF(1>=Assumptions!B$54,Assumptions!B$40,0) | C21: =IF(2>=Assumptions!B$54,Assumptions!B$40,0) | D21: =IF(3>=Assumptions!B$54,Assumptions!B$40,0) | E21: =IF(4>=Assumptions!B$54,Assumptions!B$40,0) | F21: =IF(5>=Assumptions!B$54,Assumptions!B$40,0) | G21: =IF(6>=Assumptions!B$54,Assumptions!B$40,0) | H21: =IF(7>=Assumptions!B$54,Assumptions!B$40,0) | I21: =IF(8>=Assumptions!B$54,Assumptions!B$40,0) | J21: =IF(9>=Assumptions!B$54,Assumptions!B$40,0) | K21: =IF(10>=Assumptions!B$54,Assumptions!B$40,0) | L21: =IF(11>=Assumptions!B$54,Assumptions!B$40,0) | M21: =IF(12>=Assumptions!B$54,Assumptions!B$40,0) | N21: =IF(13>=Assumptions!B$54,Assumptions!B$40,0) | O21: =IF(14>=Assumptions!B$54,Assumptions!B$40,0) | P21: =IF(15>=Assumptions!B$54,Assumptions!B$40,0) | Q21: =IF(16>=Assumptions!B$54,Assumptions!B$40,0) | R21: =IF(17>=Assumptions!B$54,Assumptions!B$40,0) | S21: =IF(18>=Assumptions!B$54,Assumptions!B$40,0) | T21: =IF(19>=Assumptions!B$54,Assumptions!B$40,0) | U21: =IF(20>=Assumptions!B$54,Assumptions!B$40,0) | V21: =IF(21>=Assumptions!B$54,Assumptions!B$40,0) | W21: =IF(22>=Assumptions!B$54,Assumptions!B$40,0) | X21: =IF(23>=Assumptions!B$54,Assumptions!B$40,0) | Y21: =IF(24>=Assumptions!B$54,Assumptions!B$40,0) | Z21: =IF(25>=Assumptions!B$54,Assumptions!B$40,0) | AA21: =IF(26>=Assumptions!B$54,Assumptions!B$40,0) | AB21: =IF(27>=Assumptions!B$54,Assumptions!B$40,0) | AC21: =IF(28>=Assumptions!B$54,Assumptions!B$40,0) | AD21: =IF(29>=Assumptions!B$54,Assumptions!B$40,0) | AE21: =IF(30>=Assumptions!B$54,Assumptions!B$40,0) | AF21: =IF(31>=Assumptions!B$54,Assumptions!B$40,0) | AG21: =IF(32>=Assumptions!B$54,Assumptions!B$40,0) | AH21: =IF(33>=Assumptions!B$54,Assumptions!B$40,0) | AI21: =IF(34>=Assumptions!B$54,Assumptions!B$40,0) | AJ21: =IF(35>=Assumptions!B$54,Assumptions!B$40,0) | AK21: =IF(36>=Assumptions!B$54,Assumptions!B$40,0) | AL21: =SUM(B21:M21) | AM21: =SUM(N21:Y21) | AN21: =SUM(Z21:AK21)
A22: Cloud + infra | B22: =Assumptions!B$41 | C22: =Assumptions!B$41 | D22: =Assumptions!B$41 | E22: =Assumptions!B$41 | F22: =Assumptions!B$41 | G22: =Assumptions!B$41 | H22: =Assumptions!B$41 | I22: =Assumptions!B$41 | J22: =Assumptions!B$41 | K22: =Assumptions!B$41 | L22: =Assumptions!B$41 | M22: =Assumptions!B$41 | N22: =Assumptions!B$41 | O22: =Assumptions!B$41 | P22: =Assumptions!B$41 | Q22: =Assumptions!B$41 | R22: =Assumptions!B$41 | S22: =Assumptions!B$41 | T22: =Assumptions!B$41 | U22: =Assumptions!B$41 | V22: =Assumptions!B$41 | W22: =Assumptions!B$41 | X22: =Assumptions!B$41 | Y22: =Assumptions!B$41 | Z22: =Assumptions!B$41 | AA22: =Assumptions!B$41 | AB22: =Assumptions!B$41 | AC22: =Assumptions!B$41 | AD22: =Assumptions!B$41 | AE22: =Assumptions!B$41 | AF22: =Assumptions!B$41 | AG22: =Assumptions!B$41 | AH22: =Assumptions!B$41 | AI22: =Assumptions!B$41 | AJ22: =Assumptions!B$41 | AK22: =Assumptions!B$41 | AL22: =SUM(B22:M22) | AM22: =SUM(N22:Y22) | AN22: =SUM(Z22:AK22)
A23: AI/LLM API spend | B23: =Assumptions!B$42+(B6+B7)*Assumptions!B$43 | C23: =Assumptions!B$42+(C6+C7)*Assumptions!B$43 | D23: =Assumptions!B$42+(D6+D7)*Assumptions!B$43 | E23: =Assumptions!B$42+(E6+E7)*Assumptions!B$43 | F23: =Assumptions!B$42+(F6+F7)*Assumptions!B$43 | G23: =Assumptions!B$42+(G6+G7)*Assumptions!B$43 | H23: =Assumptions!B$42+(H6+H7)*Assumptions!B$43 | I23: =Assumptions!B$42+(I6+I7)*Assumptions!B$43 | J23: =Assumptions!B$42+(J6+J7)*Assumptions!B$43 | K23: =Assumptions!B$42+(K6+K7)*Assumptions!B$43 | L23: =Assumptions!B$42+(L6+L7)*Assumptions!B$43 | M23: =Assumptions!B$42+(M6+M7)*Assumptions!B$43 | N23: =Assumptions!B$42+(N6+N7)*Assumptions!B$43 | O23: =Assumptions!B$42+(O6+O7)*Assumptions!B$43 | P23: =Assumptions!B$42+(P6+P7)*Assumptions!B$43 | Q23: =Assumptions!B$42+(Q6+Q7)*Assumptions!B$43 | R23: =Assumptions!B$42+(R6+R7)*Assumptions!B$43 | S23: =Assumptions!B$42+(S6+S7)*Assumptions!B$43 | T23: =Assumptions!B$42+(T6+T7)*Assumptions!B$43 | U23: =Assumptions!B$42+(U6+U7)*Assumptions!B$43 | V23: =Assumptions!B$42+(V6+V7)*Assumptions!B$43 | W23: =Assumptions!B$42+(W6+W7)*Assumptions!B$43 | X23: =Assumptions!B$42+(X6+X7)*Assumptions!B$43 | Y23: =Assumptions!B$42+(Y6+Y7)*Assumptions!B$43 | Z23: =Assumptions!B$42+(Z6+Z7)*Assumptions!B$43 | AA23: =Assumptions!B$42+(AA6+AA7)*Assumptions!B$43 | AB23: =Assumptions!B$42+(AB6+AB7)*Assumptions!B$43 | AC23: =Assumptions!B$42+(AC6+AC7)*Assumptions!B$43 | AD23: =Assumptions!B$42+(AD6+AD7)*Assumptions!B$43 | AE23: =Assumptions!B$42+(AE6+AE7)*Assumptions!B$43 | AF23: =Assumptions!B$42+(AF6+AF7)*Assumptions!B$43 | AG23: =Assumptions!B$42+(AG6+AG7)*Assumptions!B$43 | AH23: =Assumptions!B$42+(AH6+AH7)*Assumptions!B$43 | AI23: =Assumptions!B$42+(AI6+AI7)*Assumptions!B$43 | AJ23: =Assumptions!B$42+(AJ6+AJ7)*Assumptions!B$43 | AK23: =Assumptions!B$42+(AK6+AK7)*Assumptions!B$43 | AL23: =SUM(B23:M23) | AM23: =SUM(N23:Y23) | AN23: =SUM(Z23:AK23)
A24: Tools & SaaS | B24: =Assumptions!B$44 | C24: =Assumptions!B$44 | D24: =Assumptions!B$44 | E24: =Assumptions!B$44 | F24: =Assumptions!B$44 | G24: =Assumptions!B$44 | H24: =Assumptions!B$44 | I24: =Assumptions!B$44 | J24: =Assumptions!B$44 | K24: =Assumptions!B$44 | L24: =Assumptions!B$44 | M24: =Assumptions!B$44 | N24: =Assumptions!B$44 | O24: =Assumptions!B$44 | P24: =Assumptions!B$44 | Q24: =Assumptions!B$44 | R24: =Assumptions!B$44 | S24: =Assumptions!B$44 | T24: =Assumptions!B$44 | U24: =Assumptions!B$44 | V24: =Assumptions!B$44 | W24: =Assumptions!B$44 | X24: =Assumptions!B$44 | Y24: =Assumptions!B$44 | Z24: =Assumptions!B$44 | AA24: =Assumptions!B$44 | AB24: =Assumptions!B$44 | AC24: =Assumptions!B$44 | AD24: =Assumptions!B$44 | AE24: =Assumptions!B$44 | AF24: =Assumptions!B$44 | AG24: =Assumptions!B$44 | AH24: =Assumptions!B$44 | AI24: =Assumptions!B$44 | AJ24: =Assumptions!B$44 | AK24: =Assumptions!B$44 | AL24: =SUM(B24:M24) | AM24: =SUM(N24:Y24) | AN24: =SUM(Z24:AK24)
A25: Legal & accounting | B25: =Assumptions!B$45 | C25: =Assumptions!B$45 | D25: =Assumptions!B$45 | E25: =Assumptions!B$45 | F25: =Assumptions!B$45 | G25: =Assumptions!B$45 | H25: =Assumptions!B$45 | I25: =Assumptions!B$45 | J25: =Assumptions!B$45 | K25: =Assumptions!B$45 | L25: =Assumptions!B$45 | M25: =Assumptions!B$45 | N25: =Assumptions!B$45 | O25: =Assumptions!B$45 | P25: =Assumptions!B$45 | Q25: =Assumptions!B$45 | R25: =Assumptions!B$45 | S25: =Assumptions!B$45 | T25: =Assumptions!B$45 | U25: =Assumptions!B$45 | V25: =Assumptions!B$45 | W25: =Assumptions!B$45 | X25: =Assumptions!B$45 | Y25: =Assumptions!B$45 | Z25: =Assumptions!B$45 | AA25: =Assumptions!B$45 | AB25: =Assumptions!B$45 | AC25: =Assumptions!B$45 | AD25: =Assumptions!B$45 | AE25: =Assumptions!B$45 | AF25: =Assumptions!B$45 | AG25: =Assumptions!B$45 | AH25: =Assumptions!B$45 | AI25: =Assumptions!B$45 | AJ25: =Assumptions!B$45 | AK25: =Assumptions!B$45 | AL25: =SUM(B25:M25) | AM25: =SUM(N25:Y25) | AN25: =SUM(Z25:AK25)
A26: Marketing & content | B26: =Assumptions!B$46 | C26: =Assumptions!B$46 | D26: =Assumptions!B$46 | E26: =Assumptions!B$46 | F26: =Assumptions!B$46 | G26: =Assumptions!B$46 | H26: =Assumptions!B$46 | I26: =Assumptions!B$46 | J26: =Assumptions!B$46 | K26: =Assumptions!B$46 | L26: =Assumptions!B$46 | M26: =Assumptions!B$46 | N26: =Assumptions!B$46 | O26: =Assumptions!B$46 | P26: =Assumptions!B$46 | Q26: =Assumptions!B$46 | R26: =Assumptions!B$46 | S26: =Assumptions!B$46 | T26: =Assumptions!B$46 | U26: =Assumptions!B$46 | V26: =Assumptions!B$46 | W26: =Assumptions!B$46 | X26: =Assumptions!B$46 | Y26: =Assumptions!B$46 | Z26: =Assumptions!B$46 | AA26: =Assumptions!B$46 | AB26: =Assumptions!B$46 | AC26: =Assumptions!B$46 | AD26: =Assumptions!B$46 | AE26: =Assumptions!B$46 | AF26: =Assumptions!B$46 | AG26: =Assumptions!B$46 | AH26: =Assumptions!B$46 | AI26: =Assumptions!B$46 | AJ26: =Assumptions!B$46 | AK26: =Assumptions!B$46 | AL26: =SUM(B26:M26) | AM26: =SUM(N26:Y26) | AN26: =SUM(Z26:AK26)
A27: TOTAL COSTS | B27: =SUM(B16:B26) | C27: =SUM(C16:C26) | D27: =SUM(D16:D26) | E27: =SUM(E16:E26) | F27: =SUM(F16:F26) | G27: =SUM(G16:G26) | H27: =SUM(H16:H26) | I27: =SUM(I16:I26) | ... AK27: =SUM(AK16:AK26) | AL27: =SUM(B27:M27) | AM27: =SUM(N27:Y27) | AN27: =SUM(Z27:AK27)
A28: NET BURN (€/mo) | B28: =B27-B13 | C28: =C27-C13 | D28: =D27-D13 | E28: =E27-E13 | F28: =F27-F13 | G28: =G27-G13 | H28: =H27-H13 | I28: =I27-I13 | ... AK28: =AK27-AK13 | AL28: =SUM(B28:M28) | AM28: =SUM(N28:Y28) | AN28: =SUM(Z28:AK28)

Sheet Unit Economics
A1: Unit Economics
A2: Per-customer economics by tier · Steady-state assumptions
A4: Metric | B4: Tier 1 (Connect) | C4: Tier 2 (Compete) | D4: Tier 3 (Dominate) | E4: Enterprise
A5: ARPA — monthly (€) | B5: =Assumptions!B18 | C5: =Assumptions!B19 | D5: =Assumptions!B20 | E5: =Assumptions!B22/12
A6: ARPA — annual (€) | B6: =B5*12 | C6: =C5*12 | D6: =D5*12 | E6: =Assumptions!B22
A7: COGS — per customer per month (€) [AI + infra share] | B7: 12 | C7: 28 | D7: 55 | E7: 250
A8: Gross margin per customer per month (€) | B8: =B5-B7 | C8: =C5-C7 | D8: =D5-D7 | E8: =B6/12-E7
A9: Gross margin % | B9: =B8/B5 | C9: =C8/C5 | D9: =D8/D5 | E9: =E8/(E6/12)
A10: Avg monthly logo churn | B10: 0.05 | C10: 0.035 | D10: 0.02 | E10: 0.05
A11: Avg customer lifetime (months) = 1/churn | B11: =1/B10 | C11: =1/C10 | D11: =1/D10 | E11: =1/E10
A12: LTV (€) = ARPA × lifetime × margin % | B12: =B5*B11*B9 | C12: =C5*C11*C9 | D12: =D5*D11*D9 | E12: =(E6/12)*E11*E9
A13: CAC — blended (€) [estimate] | B13: 250 | C13: 700 | D13: 1800 | E13: 8500
A14: LTV / CAC ratio | B14: =B12/B13 | C14: =C12/C13 | D14: =D12/D13 | E14: =E12/E13
A15: CAC payback (months) = CAC / (ARPA × margin %) | B15: =B13/(B5*B9) | C15: =C13/(C5*C9) | D15: =D13/(D5*D9) | E15: =E13/((E6/12)*E9)
A17: Notes
A18: Tier 1 is self-serve (low CAC via Shopify App Store organic + free scan). Tier 3 has higher CAC from sales-led motion.
A19: Enterprise CAC includes 12-week pilot delivery cost — pilots are positioned as free at Year 1 to lower the barrier.
A20: Industry benchmark for early-stage SaaS: LTV/CAC > 3:1, CAC payback < 12 months. Tier 1 hits both immediately due to organic acquisition.
A21: All COGS figures are estimates based on observed AI/LLM API spend per simulation × monthly scan cadence per tier.

Sheet Burn & Runway
A1: Burn & Runway Analysis
A2: Pre-raise vs. post-raise scenarios. Driven by P&L 36 Months tab.
A4: PRE-RAISE (today, June 2026) | H4: RUNWAY SUMMARY
A5: Cash on hand | B5: =Assumptions!B6 | H5: Cash at start of M1 (post-raise) | I5: =Assumptions!B6+Assumptions!B12
A6: Current MRR | B6: =Assumptions!B7 | H6: Cash at end of Year 1 | I6: =F26
A7: Current burn (€/mo) | B7: =Assumptions!B8 | H7: Cash at end of Year 2 | I7: =F38
A8: Net burn (burn − MRR) | B8: =B7-B6 | H8: Cash at end of Year 3 | I8: =F50
A9: Runway at current burn (months) | B9: =IF(B8<=0,"infinite",B5/B8)
A10: Runway warning threshold (months) | B10: 3 | H10: Y1 net burn | I10: ='P&L 36 Months'!AL28
H11: Y2 net burn | I11: ='P&L 36 Months'!AM28
A12: POST-RAISE (assumes €300K closes M1) | H12: Y3 net burn (positive = profitable!) | I12: ='P&L 36 Months'!AN28
A13: Cash position over time
A14: Month | B14: Cash in (€) | C14: Revenue (€) | D14: Costs (€) | E14: Net cash flow (€) | F14: End-of-month cash (€)
A15: M1 | B15: =Assumptions!B12 | C15: ='P&L 36 Months'!B13 | D15: ='P&L 36 Months'!B27 | E15: =B15+C15-D15 | F15: =Assumptions!B6+E15
A16: M2 | B16: 0 | C16: ='P&L 36 Months'!C13 | D16: ='P&L 36 Months'!C27 | E16: =B16+C16-D16 | F16: =F15+E16
A17: M3 | B17: 0 | C17: ='P&L 36 Months'!D13 | D17: ='P&L 36 Months'!D27 | E17: =B17+C17-D17 | F17: =F16+E17
A18: M4 | B18: 0 | C18: ='P&L 36 Months'!E13 | D18: ='P&L 36 Months'!E27 | E18: =B18+C18-D18 | F18: =F17+E18
A19: M5 | B19: 0 | C19: ='P&L 36 Months'!F13 | D19: ='P&L 36 Months'!F27 | E19: =B19+C19-D19 | F19: =F18+E19
A20: M6 | B20: 0 | C20: ='P&L 36 Months'!G13 | D20: ='P&L 36 Months'!G27 | E20: =B20+C20-D20 | F20: =F19+E20
A21: M7 | B21: 0 | C21: ='P&L 36 Months'!H13 | D21: ='P&L 36 Months'!H27 | E21: =B21+C21-D21 | F21: =F20+E21
A22: M8 | B22: 0 | C22: ='P&L 36 Months'!I13 | D22: ='P&L 36 Months'!I27 | E22: =B22+C22-D22 | F22: =F21+E22
A23: M9 | B23: 0 | C23: ='P&L 36 Months'!J13 | D23: ='P&L 36 Months'!J27 | E23: =B23+C23-D23 | F23: =F22+E23
A24: M10 | B24: 0 | C24: ='P&L 36 Months'!K13 | D24: ='P&L 36 Months'!K27 | E24: =B24+C24-D24 | F24: =F23+E24
A25: M11 | B25: 0 | C25: ='P&L 36 Months'!L13 | D25: ='P&L 36 Months'!L27 | E25: =B25+C25-D25 | F25: =F24+E25
A26: M12 | B26: 0 | C26: ='P&L 36 Months'!M13 | D26: ='P&L 36 Months'!M27 | E26: =B26+C26-D26 | F26: =F25+E26
A27: M13 | B27: 0 | C27: ='P&L 36 Months'!N13 | D27: ='P&L 36 Months'!N27 | E27: =B27+C27-D27 | F27: =F26+E27
A28: M14 | B28: 0 | C28: ='P&L 36 Months'!O13 | D28: ='P&L 36 Months'!O27 | E28: =B28+C28-D28 | F28: =F27+E28
A29: M15 | B29: 0 | C29: ='P&L 36 Months'!P13 | D29: ='P&L 36 Months'!P27 | E29: =B29+C29-D29 | F29: =F28+E29
A30: M16 | B30: 0 | C30: ='P&L 36 Months'!Q13 | D30: ='P&L 36 Months'!Q27 | E30: =B30+C30-D30 | F30: =F29+E30
A31: M17 | B31: 0 | C31: ='P&L 36 Months'!R13 | D31: ='P&L 36 Months'!R27 | E31: =B31+C31-D31 | F31: =F30+E31
A32: M18 | B32: 0 | C32: ='P&L 36 Months'!S13 | D32: ='P&L 36 Months'!S27 | E32: =B32+C32-D32 | F32: =F31+E32
A33: M19 | B33: 0 | C33: ='P&L 36 Months'!T13 | D33: ='P&L 36 Months'!T27 | E33: =B33+C33-D33 | F33: =F32+E33
A34: M20 | B34: 0 | C34: ='P&L 36 Months'!U13 | D34: ='P&L 36 Months'!U27 | E34: =B34+C34-D34 | F34: =F33+E34
A35: M21 | B35: 0 | C35: ='P&L 36 Months'!V13 | D35: ='P&L 36 Months'!V27 | E35: =B35+C35-D35 | F35: =F34+E35
A36: M22 | B36: 0 | C36: ='P&L 36 Months'!W13 | D36: ='P&L 36 Months'!W27 | E36: =B36+C36-D36 | F36: =F35+E36
A37: M23 | B37: 0 | C37: ='P&L 36 Months'!X13 | D37: ='P&L 36 Months'!X27 | E37: =B37+C37-D37 | F37: =F36+E37
A38: M24 | B38: 0 | C38: ='P&L 36 Months'!Y13 | D38: ='P&L 36 Months'!Y27 | E38: =B38+C38-D38 | F38: =F37+E38
A39: M25 | B39: 0 | C39: ='P&L 36 Months'!Z13 | D39: ='P&L 36 Months'!Z27 | E39: =B39+C39-D39 | F39: =F38+E39
A40: M26 | B40: 0 | C40: ='P&L 36 Months'!AA13 | D40: ='P&L 36 Months'!AA27 | E40: =B40+C40-D40 | F40: =F39+E40
A41: M27 | B41: 0 | C41: ='P&L 36 Months'!AB13 | D41: ='P&L 36 Months'!AB27 | E41: =B41+C41-D41 | F41: =F40+E41
...

Sheet Use of Funds
A1: Use of Funds — €300K Raise
A2: 12-month deployment plan against the seed round
A4: Category | B4: % of round | C4: € amount | D4: What it funds
A5: Engineering | B5: 0.4 | C5: =B5*Assumptions!B$12 | D5: Two engineering hires (back-end + full-stack), cloud infra scaling, model API budget
A6: GTM (sales & marketing) | B6: 0.3 | C6: =B6*Assumptions!B$12 | D6: GTM/Sales Lead hire, Shopify App Store launch campaign, content/SEO, paid acquisition tests
A7: Activation + runway | B7: 0.3 | C7: =B7*Assumptions!B$12 | D7: Founder salaries (from M3), customer success, legal & compliance, contingency
A8: TOTAL | B8: =SUM(B5:B7) | C8: =SUM(C5:C7)
A10: MILESTONES THE RAISE UNLOCKS
A11: Quarter | B11: Milestone
A12: Q3 2026 | B12: Shopify App Store listing live, write-back enabled, first 25 paying merchants
A13: Q4 2026 | B13: 100 paying merchants on Tier 1+, 1 enterprise pilot signed
A14: Q1 2027 | B14: WooCommerce integration live, BigCommerce in beta, 2nd enterprise pilot
A15: Q2 2027 (EoY1) | B15: €450K ARR, 2 enterprise pilots delivered, SOC 2 Type I engagement complete
